Workbook

Sheet Ejercicios
A1: Ejercicio | B1: 1 RM (1er fase) | C1: Objetivo
A2: Arranque de potencia colgado | B2: 85 | C2: 90
A3: Cargada de potencia colgado | B3: 115 | C3: 120
A4: Arranque de potencia | B4: 80
A5: Cargada de potencia | B5: 110
A6: Arranque de colgado | B6: 90
A7: Cargada de colgado | B7: 115
A8: Arranque | B8: 90
A9: Cargada | B9: 115
A10: Sentadilla | B10: 140
A11: Sentadila frontal | B11: 130
A12: Press frontal con impulso | B12: 90 | C12: 95
A13: Press frontal | B13: 60
A14: Empuje de barra | B14: 30
A15: Press con manuerna arrodillado
A16: Empuje con mancuerna
A17: Press banco plano | B17: 90
A18: Press banco plano con mancuerna | B18: 25
A19: Press banco inclinado
A20: Press banco inclinado con mancuerna
A21: Fondos | B21: 50
A22: Dominadas prono | B22: 30
A23: Dominadas supina | B23: 25
A24: Remo acostado
A25: Remo inclinado
A26: Remo con mancuerna | B26: 40
A27: Biceps con barra w
A28: Biceps con mancuerna
A29: Triceps tras nuca
A30: Triceps frontal
A31: Tiron de cargada | B31: 180
A32: Tiron de arranque | B32: 120
A33: Bulgaras (mancuerna) | B33: 30
A34: NIVEL 1 A
A35: NIVEL 1 B
A36: NIVEL 1 C
A37: NIVEL 2 A
A38: NIVEL 2 B
A39: NIVEL 2 C
A40: NIVEL 3 A
...

Sheet Pliometria
A1: NIVEL 1 A | B1: Con 2 pies, dos saltos delante y uno atras | C1: 2 pies salto de costado | D1: 1 pie, en el lugar, salto adelante y atras | E1: 1 pie, en sentido del reloj, arrancando del centro para adelante, saltar y volver siempre al centro | F1: 1 pie, salto en el lugar a los costados | G1: Salto con soga
A2: NIVEL 1 B | B2: 1 pie en cada cajon y salto rapido en el lugar | C2: Pie de adelante en cajon y salto con el de atras | D2: Pie de atras en cajón, con el de delante salto a los costados sobre obstaculo bajo | E2: Del piso, subo el pie delantero al cajon (pie de atras en el piso) | F2: Del centro a cajones con una pierna | G2: Del centro con ambas piernas, rotando piernas delantera a cajon
A3: NIVEL 1 C | B3: Del centro, al costado, al centro, al otro costado, centro, adelante, atras [2] | C3: Delante dos veces, vuelvo de costado izquierdo y luego derecho [3] | D3: Lado a lado salto sobre cajon [2] | E3: 1 pie delante al cajón, bajo, izquierda y derecha, subo [1] | F3: Entre 2 cajones, del centro, izquierda centro derecha [1] | G3: 1 pie salto al cajon, caigo al piso, izquierda centro derecha, atras al cajon, caigo, izquierda centro derecha y repito [1]
A4: NIVEL 2 A
A5: NIVEL 2 B
A6: NIVEL 2 C
A7: NIVEL 3 A
A8: NIVEL 3 B
A9: NIVEL 3 C

Sheet Calculos
A1: TABLA DE PORCENTAJES
A2: Microciclos y variante | C2: Mic1 Vol% | D2: Mic2 Vol% | E2: Mic3 Vol% | F2: Mic4 Vol% | G2: Mic5 Vol% | H2: Mic1 IMR | I2: Mic2 IMR | J2: Mic3 IMR | K2: Mic4 IMR | L2: Mic5 IMR
B3: 5A | C3: 21 | D3: 23 | E3: 26 | F3: 18 | G3: 12 | H3: 0 | I3: -1 | J3: -2 | K3: 2 | L3: 3
B4: 5B | C4: 20 | D4: 22 | E4: 25 | F4: 18 | G4: 15 | H4: 0 | I4: -1 | J4: -2 | K4: 1 | L4: 3
B5: 4A | C5: 28 | D5: 22 | E5: 32 | F5: 18 | H5: 0 | I5: 2 | J5: -3 | K5: 3
B6: 4B | C6: 22 | D6: 28 | E6: 32 | F6: 18 | H6: 2 | I6: 0 | J6: -3 | K6: 3
B7: 4C | C7: 24 | D7: 26 | E7: 28 | F7: 22 | H7: 1 | I7: -1 | J7: -2 | K7: 2
B8: 3A | C8: 20 | D8: 30 | E8: 50 | H8: 4 | I8: 2 | J8: -3
B9: 3B | C9: 25 | D9: 35 | E9: 40 | H9: 3 | I9: 1 | J9: -2
B10: 3C | C10: 20 | D10: 35 | E10: 45 | H10: 4 | I10: 2 | J10: -3
B11: 2A | C11: 40 | D11: 60 | H11: 5 | I11: -3
B12: 2B | C12: 45 | D12: 55 | H12: 3 | I12: -3
A13: Frecuencia porcentual | B13: Día 1 | C13: Día 2 | D13: Día 3 | E13: Día 4 | F13: Día 5
A14: 3 | B14: 0.35 | C14: 0.45 | D14: 0.2
A15: 4 | B15: 0.26 | C15: 0.24 | D15: 0.28 | E15: 0.22
A16: 5 | B16: 0.2 | C16: 0.15 | D16: 0.3 | E16: 0.1 | F16: 0.25
A17: NIVEL 1 | D17: TOTAL | E17: IMR % | F17: Repeticiones | G17: Volumen
A18: 250 | B18: 300 | C18: 250 | D18: =A18+B18+C18 -> 800 | E18: <70% | F18: 46087 | G18: 18-30
A19: 300 | B19: 250 | C19: 300 | D19: =A19+B19+C19 -> 850 | E19: 70%-79% | F19: 46087 | G19: 46380
A20: 300 | B20: 300 | C20: 300 | D20: =A20+B20+C20 -> 900 | E20: 80%-89% | F20: 46057 | G20: 46315
A21: 350 | B21: 300 | C21: 350 | D21: =A21+B21+C21 -> 1000 | E21: >90% | F21: 46024 | G21: 46122
A22: NIVEL 2 | D22: TOTAL | F22: Dia 1 | G22: Dia 2
A23: 250 | B23: 250 | C23: 200 | D23: =A23+B23+C23 -> 700 | E23: Series de | F23: 6 | G23: 4
A24: 300 | B24: 250 | C24: 250 | D24: =A24+B24+C24 -> 800 | F24: 5 | G24: 3
A25: 300 | B25: 300 | C25: 250 | D25: =A25+B25+C25 -> 850 | F25: 6 | G25: 4
A26: 300 | B26: 300 | C26: 300 | D26: =A26+B26+C26 -> 900 | F26: 4 | G26: 2
A27: NIVEL 3 | D27: TOTAL
A28: 250 | C28: 300 | D28: =A28+C28 -> 550
A29: 300 | C29: 300 | D29: =A29+C29 -> 600
A30: 350 | C30: 300 | D30: =A30+C30 -> 650
A31: 350 | C31: 350 | D31: =A31+C31 -> 700

Sheet Ref
A1: IMR % | B1: 0.55 | C1: 0.6 | D1: 0.65 | E1: 0.7 | F1: 0.75 | G1: 0.8 | H1: 0.85 | I1: 0.9 | J1: 0.95 | K1: 1 | L1: % PESO
A2: 0.6 | B2: 0.55 | C2: 0.4 | D2: 0.15 | E2: 0.1 | L2: REPETICIONES %
A3: 0.61 | B3: 0.3 | C3: 0.35 | D3: 0.2 | E3: 0.15
A4: 0.62 | B4: 0.25 | C4: 0.3 | D4: 0.25 | E4: 0.2
A5: 0.63 | B5: 0.2 | C5: 0.35 | D5: 0.2 | E5: 0.15 | F5: 0.1
A6: 0.64 | B6: 0.15 | C6: 0.25 | D6: 0.35 | E6: 0.15 | F6: 0.1
A7: 0.65 | B7: 0.15 | C7: 0.2 | D7: 0.3 | E7: 0.15 | F7: 0.15
A8: 0.66 | B8: 0.14 | C8: 0.18 | D8: 0.3 | E8: 0.18 | F8: 0.15 | G8: 0.08
A9: 0.67 | B9: 0.1 | C9: 0.2 | D9: 0.25 | E9: 0.2 | F9: 0.15 | G9: 0.1
A10: 0.68 | B10: 0.1 | C10: 0.18 | D10: 0.2 | E10: 0.26 | F10: 0.12 | G10: 0.08 | H10: 0.06
A11: 0.69 | B11: 0.1 | C11: 0.15 | D11: 0.18 | E11: 0.25 | F11: 0.14 | G11: 0.1 | H11: 0.08
A12: 0.7 | B12: 0.12 | C12: 0.14 | D12: 0.16 | E12: 0.18 | F12: 0.16 | G12: 0.12 | H12: 0.08 | I12: 0.04
A13: 0.71 | B13: 0.1 | C13: 0.12 | D13: 0.14 | E13: 0.16 | F13: 0.24 | G13: 0.12 | H13: 0.08 | I13: 0.04
A14: 0.72 | B14: 0.08 | C14: 0.12 | D14: 0.14 | E14: 0.16 | F14: 0.18 | G14: 0.16 | H14: 0.12 | I14: 0.04
A15: 0.73 | B15: 0.08 | C15: 0.1 | D15: 0.12 | E15: 0.16 | F15: 0.18 | G15: 0.16 | H15: 0.14 | I15: 0.06
A16: 0.74 | B16: 0.08 | C16: 0.1 | D16: 0.11 | E16: 0.12 | F16: 0.13 | G16: 0.22 | H16: 0.18 | I16: 0.06
A17: 0.75 | B17: 0.08 | C17: 0.07 | D17: 0.12 | E17: 0.11 | F17: 0.13 | G17: 0.22 | H17: 0.18 | I17: 0.06 | J17: 0.03
A18: 0.76 | B18: 0.06 | C18: 0.07 | D18: 0.11 | E18: 0.12 | F18: 0.13 | G18: 0.21 | H18: 0.19 | I18: 0.06 | J18: 0.03 | K18: 0.02
A19: 0.77 | B19: 0.06 | C19: 0.06 | D19: 0.09 | E19: 0.12 | F19: 0.13 | G19: 0.2 | H19: 0.2 | I19: 0.07 | J19: 0.04 | K19: 0.03
A20: 0.78 | B20: 0.06 | C20: 0.06 | D20: 0.09 | E20: 0.09 | F20: 0.12 | G20: 0.19 | H20: 0.21 | I20: 0.08 | J20: 0.06 | K20: 0.04
A21: 0.79 | B21: 0.06 | C21: 0.06 | D21: 0.09 | E21: 0.09 | F21: 0.09 | G21: 0.15 | H21: 0.22 | I21: 0.11 | J21: 0.08 | K21: 0.05
A22: 0.8 | B22: 0.06 | C22: 0.06 | D22: 0.09 | E22: 0.09 | F22: 0.09 | G22: 0.12 | H22: 0.15 | I22: 0.17 | J22: 0.09 | K22: 0.08
A25: 0.55 | B25: 0.6 | C25: 0.65 | D25: 0.7 | E25: 0.75 | F25: 0.8 | G25: 0.85 | H25: 0.9 | I25: %IMR | J25: Rep. Microciclo
A26: =ROUND(J26*B16,0) -> 13 | B26: =ROUND(J26*C16,0) -> 16 | C26: =ROUND(J26*D16,0) -> 18 | D26: =ROUND(J26*E16,0) -> 20 | E26: =ROUND(J26*F16,0) -> 21 | F26: =ROUND(J26*G16,0) -> 36 | G26: =ROUND(J26*H16,0) -> 29 | H26: =ROUND(J26*I16,0) -> 10 | I26: 0.74 | J26: 163

Sheet Entrenamiento
F1: CALENTAMIENTO
G2: Lumbares en banco-Twist sovietico-Trimado | M2: Lumbares en banco-Twist sovietico-Trimado | R2: Lumbares en banco-Twist sovietico-Trimado | X2: Lumbares en banco-Twist sovietico-Trimado | AD2: Lumbares en banco-Twist sovietico-Trimado
A3: MICROCICLO 1 | B3: MICROCICLO 2 | C3: MICROCICLO 3 | D3: MICROCICLO 4 | E3: MICROCICLO 5 | I3: Cargada de potencia colgado | O3: Cargada de potencia colgado | U3: Cargada de potencia colgado
A4: Potencia | B4: Potencia | C4: Potencia | D4: Potencia | E4: Potencia | F4: KG | G4: DIA 1 | H4: DIA 1 | I4: DIA 1 | J4: DIA 1 | K4: DIA 1 | L4: KG | M4: DIA 2 | N4: DIA 2 | O4: DIA 2 | P4: DIA 2 | Q4: DIA 2 | R4: KG | S4: DIA 3 | T4: DIA 3 | U4: DIA 3 | V4: DIA 3 | W4: DIA 3 | X4: KG | Y4: DIA 4 | Z4: DIA 4 | AA4: DIA 4 | AB4: DIA 4 | AC4: DIA 4 | AD4: KG | AE4: DIA 5 | AF4: DIA 5 | AG4: DIA 5 | AH4: DIA 5 | AI4: DIA 5
F5: Repeticiones | G5: =ROUND(VLOOKUP(Programacion!$I$4, Calculos!$A$14:$F$16, 2, 0)*(VLOOKUP(Programacion!$I$2 & Programacion!$I$3, Calculos!$B$3:$L$12, 2, 0)/100)*Programacion!$I$8,0)-SUM(Entrenamiento!$G$6:$G$15) -> -5 | H5: =ROUND(VLOOKUP(Programacion!$I$4, Calculos!$A$14:$F$16, 2, 0)*(VLOOKUP(Programacion!$I$2 & Programacion!$I$3, Calculos!$B$3:$L$12, 3, 0)/100)*Programacion!$I$8,0)-SUM(Entrenamiento!$H$6:$H$15) -> 0 | I5: =ROUND(VLOOKUP(Programacion!$I$4, Calculos!$A$14:$F$16, 2, 0)*(VLOOKUP(Programacion!$I$2 & Programacion!$I$3, Calculos!$B$3:$L$12, 4, 0)/100)*Programacion!$I$8,0)-SUM(Entrenamiento!$I$6:$I$15) -> 0 | J5: =ROUND(VLOOKUP(Programacion!$I$4, Calculos!$A$14:$F$16, 2, 0)*(VLOOKUP(Programacion!$I$2 & Programacion!$I$3, Calculos!$B$3:$L$12, 5, 0)/100)*Programacion!$I$8,0)-SUM(Entrenamiento!$J$6:$J$15) -> 0 | K5: =ROUND(VLOOKUP(Programacion!$I$4, Calculos!$A$14:$F$16, 2, 0)*(VLOOKUP(Programacion!$I$2 & Programacion!$I$3, Calculos!$B$3:$L$12, 6, 0)/100)*Programacion!$I$8,0)-SUM(Entrenamiento!$K$6:$K$15) -> 0 | L5: Repeticiones | M5: =ROUND(VLOOKUP(Programacion!$I$4, Calculos!$A$14:$F$16, 3, 0)*(VLOOKUP(Programacion!$I$2 & Programacion!$I$3, Calculos!$B$3:$L$12, 2, 0)/100)*Programacion!$I$8,0)-SUM(Entrenamiento!$M$6:$M$15) -> 2 | N5: =ROUND(VLOOKUP(Programacion!$I$4, Calculos!$A$14:$F$16, 3, 0)*(VLOOKUP(Programacion!$I$2 & Programacion!$I$3, Calculos!$B$3:$L$12, 3, 0)/100)*Programacion!$I$8,0)-SUM(Entrenamiento!$N$6:$N$15) -> 0 | O5: =ROUND(VLOOKUP(Programacion!$I$4, Calculos!$A$14:$F$16, 3, 0)*(VLOOKUP(Programacion!$I$2 & Programacion!$I$3, Calculos!$B$3:$L$12, 4, 0)/100)*Programacion!$I$8,0)-SUM(Entrenamiento!$O$6:$O$15) -> 0 | P5: =ROUND(VLOOKUP(Programacion!$I$4, Calculos!$A$14:$F$16, 3, 0)*(VLOOKUP(Programacion!$I$2 & Programacion!$I$3, Calculos!$B$3:$L$12, 5, 0)/100)*Programacion!$I$8,0)-SUM(Entrenamiento!$P$6:$P$15) -> -1 | Q5: =ROUND(VLOOKUP(Programacion!$I$4, Calculos!$A$14:$F$16, 3, 0)*(VLOOKUP(Programacion!$I$2 & Programacion!$I$3, Calculos!$B$3:$L$12, 6, 0)/100)*Programacion!$I$8,0)-SUM(Entrenamiento!$Q$6:$Q$15) -> 1 | S5: =ROUND(VLOOKUP(Programacion!$I$4, Calculos!$A$14:$F$16, 4, 0)*(VLOOKUP(Programacion!$I$2 & Programacion!$I$3, Calculos!$B$3:$L$12, 2, 0)/100)*Programacion!$I$8,0)-SUM(Entrenamiento!$S$6:$S$15) -> 0 | T5: =ROUND(VLOOKUP(Programacion!$I$4, Calculos!$A$14:$F$16, 4, 0)*(VLOOKUP(Programacion!$I$2 & Programacion!$I$3, Calculos!$B$3:$L$12, 3, 0)/100)*Programacion!$I$8,0)-SUM(Entrenamiento!$T$6:$T$15) -> 0 | U5: =ROUND(VLOOKUP(Programacion!$I$4, Calculos!$A$14:$F$16, 4, 0)*(VLOOKUP(Programacion!$I$2 & Programacion!$I$3, Calculos!$B$3:$L$12, 4, 0)/100)*Programacion!$I$8,0)-SUM(Entrenamiento!$U$6:$U$15) -> 0 | V5: =ROUND(VLOOKUP(Programacion!$I$4, Calculos!$A$14:$F$16, 4, 0)*(VLOOKUP(Programacion!$I$2 & Programacion!$I$3, Calculos!$B$3:$L$12, 5, 0)/100)*Programacion!$I$8,0)-SUM(Entrenamiento!$V$6:$V$15) -> 0 | W5: =ROUND(VLOOKUP(Programacion!$I$4, Calculos!$A$14:$F$16, 4, 0)*(VLOOKUP(Programacion!$I$2 & Programacion!$I$3, Calculos!$B$3:$L$12, 6, 0)/100)*Programacion!$I$8,0)-SUM(Entrenamiento!$W$6:$W$15) -> 0 | Y5: =ROUND(VLOOKUP(Programacion!$I$4, Calculos!$A$14:$F$16, 5, 0)*(VLOOKUP(Programacion!$I$2 & Programacion!$I$3, Calculos!$B$3:$L$12, 2, 0)/100)*Programacion!$I$8,0)-SUM(Entrenamiento!$Y$6:$Y$15) -> 0 | Z5: =ROUND(VLOOKUP(Programacion!$I$4, Calculos!$A$14:$F$16, 5, 0)*(VLOOKUP(Programacion!$I$2 & Programacion!$I$3, Calculos!$B$3:$L$12, 3, 0)/100)*Programacion!$I$8,0)-SUM(Entrenamiento!$Z$6:$Z$15) -> 0 | AA5: =ROUND(VLOOKUP(Programacion!$I$4, Calculos!$A$14:$F$16, 5, 0)*(VLOOKUP(Programacion!$I$2 & Programacion!$I$3, Calculos!$B$3:$L$12, 4, 0)/100)*Programacion!$I$8,0)-SUM(Entrenamiento!$AA$6:$AA$15) -> 0 | AB5: =ROUND(VLOOKUP(Programacion!$I$4, Calculos!$A$14:$F$16, 5, 0)*(VLOOKUP(Programacion!$I$2 & Programacion!$I$3, Calculos!$B$3:$L$12, 5, 0)/100)*Programacion!$I$8,0)-SUM(Entrenamiento!$AB$6:$AB$15) -> 0 | AC5: =ROUND(VLOOKUP(Programacion!$I$4, Calculos!$A$14:$F$16, 5, 0)*(VLOOKUP(Programacion!$I$2 & Programacion!$I$3, Calculos!$B$3:$L$12, 6, 0)/100)*Programacion!$I$8,0)-SUM(Entrenamiento!$AC$6:$AC$15) -> 0 | AE5: =ROUND(VLOOKUP(Programacion!$I$4, Calculos!$A$14:$F$16, 6, 0)*(VLOOKUP(Programacion!$I$2 & Programacion!$I$3, Calculos!$B$3:$L$12, 2, 0)/100)*Programacion!$I$8,0)-SUM(Entrenamiento!$AE$6:$AE$15) -> 0 | AF5: =ROUND(VLOOKUP(Programacion!$I$4, Calculos!$A$14:$F$16, 6, 0)*(VLOOKUP(Programacion!$I$2 & Programacion!$I$3, Calculos!$B$3:$L$12, 3, 0)/100)*Programacion!$I$8,0)-SUM(Entrenamiento!$AF$6:$AF$15) -> 0 | AG5: =ROUND(VLOOKUP(Programacion!$I$4, Calculos!$A$14:$F$16, 6, 0)*(VLOOKUP(Programacion!$I$2 & Programacion!$I$3, Calculos!$B$3:$L$12, 4, 0)/100)*Programacion!$I$8,0)-SUM(Entrenamiento!$AG$6:$AG$15) -> 0 | AH5: =ROUND(VLOOKUP(Programacion!$I$4, Calculos!$A$14:$F$16, 6, 0)*(VLOOKUP(Programacion!$I$2 & Programacion!$I$3, Calculos!$B$3:$L$12, 5, 0)/100)*Programacion!$I$8,0)-SUM(Entrenamiento!$AH$6:$AH$15) -> 0 | AI5: =ROUND(VLOOKUP(Programacion!$I$4, Calculos!$A$14:$F$16, 6, 0)*(VLOOKUP(Programacion!$I$2 & Programacion!$I$3, Calculos!$B$3:$L$12, 6, 0)/100)*Programacion!$I$8,0)-SUM(Entrenamiento!$AI$6:$AO$15) -> 0
A6: =A7 -> -3 | B6: =B7 -> 0 | C6: =C7 -> 0 | D6: =D7 -> 0 | E6: =E7 -> 0 | F6: =round(IFERROR(VLOOKUP($I$3, Ejercicios!$A:$B, 2, FALSE) * 0.55,"55%"),0) -> 63 | G6: 6 | L6: =IFERROR(VLOOKUP($O$3, Ejercicios!$A:$B, 2, FALSE) * 0.55,"55%") -> 63.25 | M6: 6 | R6: =IFERROR(VLOOKUP($U$3, Ejercicios!$A:$B, 2, FALSE) * 0.55,"55%") -> 63.25 | S6: 4 | T6: 5 | U6: 3 | X6: =IFERROR(VLOOKUP($AA$3, Ejercicios!$A:$B, 2, FALSE) * 0.55,"55%") -> 55% | AC6: =IFERROR(ROUND(VLOOKUP(Configuracion!$I$3 & Configuracion!$I$4, Calculos!$B$19:$L$28, 6, 0)*VLOOKUP(Configuracion!$I$5, Calculos!$A$14:$F$16, 3, 0)*VLOOKUP(ROUND(VLOOKUP(Configuracion!$I$3 & Configuracion!$I$4, Calculos!$B$19:$L$28, 11, 0),0)/100, Ref!$A$2:$K$22, 2, 0), ""),"") | AD6: =IFERROR(VLOOKUP($AG$3, Ejercicios!$A:$B, 2, FALSE) * 0.55,"55%") -> 55% | AI6: =IFERROR(ROUND(VLOOKUP(Configuracion!$I$3 & Configuracion!$I$4, Calculos!$B$19:$L$28, 6, 0)*VLOOKUP(Configuracion!$I$5, Calculos!$A$14:$F$16, 3, 0)*VLOOKUP(ROUND(VLOOKUP(Configuracion!$I$3 & Configuracion!$I$4, Calculos!$B$19:$L$28, 11, 0),0)/100, Ref!$A$2:$K$22, 2, 0), ""),"")
A7: =round(((VLOOKUP(Programacion!$I$2 & Programacion!$I$3, Calculos!$B$3:$L$12, 2, 0)/100)*Programacion!$I$8)*VLOOKUP((Programacion!$I$7+(VLOOKUP(Programacion!$I$2 & Programacion!$I$3, Calculos!$B$3:$L$12, 7, 0)))/100,Ref!$A$2:$K$22,3,0),0)+round(((VLOOKUP(Programacion!$I$2 & Programacion!$I$3, Calculos!$B$3:$L$12, 2, 0)/100)*Programacion!$I$8)*VLOOKUP((Programacion!$I$7+(VLOOKUP(Programacion!$I$2 & Programacion!$I$3, Calculos!$B$3:$L$12, 7, 0)))/100,Ref!$A$2:$K$22,2,0),0)+round(((VLOOKUP(Programacion!$I$2 & Programacion!$I$3, Calculos!$B$3:$L$12, 2, 0)/100)*Programacion!$I$8)*VLOOKUP((Programacion!$I$7+(VLOOKUP(Programacion!$I$2 & Programacion!$I$3, Calculos!$B$3:$L$12, 7, 0)))/100,Ref!$A$2:$K$22,4,0),0)-SUM(Entrenamiento!$G$6:G8)-SUM(Entrenamiento!$M$6:$M$8)-SUM(Entrenamiento!$S$6:$S$8)-SUM(Entrenamiento!$Y$6:$Y$8)-SUM(Entrenamiento!$AE$6:$AE$8) -> -3 | B7: =round(((VLOOKUP(Programacion!$I$2 & Programacion!$I$3, Calculos!$B$3:$L$12, 3, 0)/100)*Programacion!$I$8)*VLOOKUP((Programacion!$I$7+(VLOOKUP(Programacion!$I$2 & Programacion!$I$3, Calculos!$B$3:$L$12, 8, 0)))/100,Ref!$A$2:$K$22,2,0),0)+round(((VLOOKUP(Programacion!$I$2 & Programacion!$I$3, Calculos!$B$3:$L$12, 3, 0)/100)*Programacion!$I$8)*VLOOKUP((Programacion!$I$7+(VLOOKUP(Programacion!$I$2 & Programacion!$I$3, Calculos!$B$3:$L$12, 8, 0)))/100,Ref!$A$2:$K$22,3,0),0)+round(((VLOOKUP(Programacion!$I$2 & Programacion!$I$3, Calculos!$B$3:$L$12, 3, 0)/100)*Programacion!$I$8)*VLOOKUP((Programacion!$I$7+(VLOOKUP(Programacion!$I$2 & Programacion!$I$3, Calculos!$B$3:$L$12, 8, 0)))/100,Ref!$A$2:$K$22,4,0),0)-SUM(Entrenamiento!$H$6:H8)-SUM(Entrenamiento!$N$6:$N$8)-SUM(Entrenamiento!$T$6:$T$8)-SUM(Entrenamiento!$Z$6:$Z$8)-SUM(Entrenamiento!$AF$6:$AF$8) -> 0 | C7: =round(((VLOOKUP(Programacion!$I$2 & Programacion!$I$3, Calculos!$B$3:$L$12, 4, 0)/100)*Programacion!$I$8)*VLOOKUP((Programacion!$I$7+(VLOOKUP(Programacion!$I$2 & Programacion!$I$3, Calculos!$B$3:$L$12, 9, 0)))/100,Ref!$A$2:$K$22,2,0),0)+round(((VLOOKUP(Programacion!$I$2 & Programacion!$I$3, Calculos!$B$3:$L$12, 4, 0)/100)*Programacion!$I$8)*VLOOKUP((Programacion!$I$7+(VLOOKUP(Programacion!$I$2 & Programacion!$I$3, Calculos!$B$3:$L$12, 9, 0)))/100,Ref!$A$2:$K$22,3,0),0)+round(((VLOOKUP(Programacion!$I$2 & Programacion!$I$3, Calculos!$B$3:$L$12, 4, 0)/100)*Programacion!$I$8)*VLOOKUP((Programacion!$I$7+(VLOOKUP(Programacion!$I$2 & Programacion!$I$3, Calculos!$B$3:$L$12, 9, 0)))/100,Ref!$A$2:$K$22,4,0),0)-SUM(Entrenamiento!$I$6:$I$8)-SUM(Entrenamiento!$O$6:O8)-SUM(Entrenamiento!$U$6:$U$8)-SUM(Entrenamiento!$AA$6:$AA$8)-SUM(Entrenamiento!$AG$6:$AG$8) -> 0 | D7: =round(((VLOOKUP(Programacion!$I$2 & Programacion!$I$3, Calculos!$B$3:$L$12, 5, 0)/100)*Programacion!$I$8)*VLOOKUP((Programacion!$I$7+(VLOOKUP(Programacion!$I$2 & Programacion!$I$3, Calculos!$B$3:$L$12, 10, 0)))/100,Ref!$A$2:$K$22,2,0),0)+round(((VLOOKUP(Programacion!$I$2 & Programacion!$I$3, Calculos!$B$3:$L$12, 5, 0)/100)*Programacion!$I$8)*VLOOKUP((Programacion!$I$7+(VLOOKUP(Programacion!$I$2 & Programacion!$I$3, Calculos!$B$3:$L$12, 10, 0)))/100,Ref!$A$2:$K$22,3,0),0)+round(((VLOOKUP(Programacion!$I$2 & Programacion!$I$3, Calculos!$B$3:$L$12, 5, 0)/100)*Programacion!$I$8)*VLOOKUP((Programacion!$I$7+(VLOOKUP(Programacion!$I$2 & Programacion!$I$3, Calculos!$B$3:$L$12, 10, 0)))/100,Ref!$A$2:$K$22,4,0),0)-SUM(Entrenamiento!$J$6:J8)-SUM(Entrenamiento!$P$6:$P$8)-SUM(Entrenamiento!$V$6:$V$8)-SUM(Entrenamiento!$AB$6:AB$8)-SUM(Entrenamiento!$AH$6:$AH$8) -> 0 | E7: =round(((VLOOKUP(Programacion!$I$2 & Programacion!$I$3, Calculos!$B$3:$L$12, 6, 0)/100)*Programacion!$I$8)*VLOOKUP((Programacion!$I$7+(VLOOKUP(Programacion!$I$2 & Programacion!$I$3, Calculos!$B$3:$L$12, 11, 0)))/100,Ref!$A$2:$K$22,2,0),0)+round(((VLOOKUP(Programacion!$I$2 & Programacion!$I$3, Calculos!$B$3:$L$12, 6, 0)/100)*Programacion!$I$8)*VLOOKUP((Programacion!$I$7+(VLOOKUP(Programacion!$I$2 & Programacion!$I$3, Calculos!$B$3:$L$12, 11, 0)))/100,Ref!$A$2:$K$22,3,0),0)+round(((VLOOKUP(Programacion!$I$2 & Programacion!$I$3, Calculos!$B$3:$L$12, 6, 0)/100)*Programacion!$I$8)*VLOOKUP((Programacion!$I$7+(VLOOKUP(Programacion!$I$2 & Programacion!$I$3, Calculos!$B$3:$L$12, 11, 0)))/100,Ref!$A$2:$K$22,4,0),0)-SUM(Entrenamiento!$K$6:K8)-SUM(Entrenamiento!$Q$6:$Q$8)-SUM(Entrenamiento!$W$6:$W$8)-SUM(Entrenamiento!AC$6:$AC$8)-SUM(Entrenamiento!$AI$6:$AI$8) -> 0 | F7: =round(IFERROR(VLOOKUP($I$3, Ejercicios!$A:$B, 2, FALSE) * 0.6,"60%") ,0) -> 69 | H7: 7 | I7: 11 | J7: 3 | K7: 2 | L7: =IFERROR(VLOOKUP($O$3, Ejercicios!$A:$B, 2, FALSE) * 0.6,"60%") -> 69 | N7: 9 | O7: 13 | P7: 9 | Q7: 4 | R7: =IFERROR(VLOOKUP($U$3, Ejercicios!$A:$B, 2, FALSE) * 0.6,"60%") -> 69 | V7: 2 | W7: 2 | X7: =IFERROR(VLOOKUP($AA$3, Ejercicios!$A:$B, 2, FALSE) * 0.6,"60%") -> 60% | AC7: =IFERROR(ROUND(VLOOKUP(Configuracion!$I$3 & Configuracion!$I$4, Calculos!$B$19:$L$28, 6, 0)*VLOOKUP(Configuracion!$I$5, Calculos!$A$14:$F$16, 3, 0)*VLOOKUP(ROUND(VLOOKUP(Configuracion!$I$3 & Configuracion!$I$4, Calculos!$B$19:$L$28, 11, 0),0)/100, Ref!$A$2:$K$22, 3, 0), 0),"") | AD7: =IFERROR(VLOOKUP($AG$3, Ejercicios!$A:$B, 2, FALSE) * 0.6,"60%") -> 60% | AI7: =IFERROR(ROUND(VLOOKUP(Configuracion!$I$3 & Configuracion!$I$4, Calculos!$B$19:$L$28, 6, 0)*VLOOKUP(Configuracion!$I$5, Calculos!$A$14:$F$16, 3, 0)*VLOOKUP(ROUND(VLOOKUP(Configuracion!$I$3 & Configuracion!$I$4, Calculos!$B$19:$L$28, 11, 0),0)/100, Ref!$A$2:$K$22, 3, 0), 0),"")
A8: =A7 -> -3 | B8: =B7 -> 0 | C8: =C7 -> 0 | D8: =D7 -> 0 | E8: =E7 -> 0 | F8: =round(IFERROR(VLOOKUP($I$3, Ejercicios!$A:$B, 2, FALSE) * 0.65,"65%") ,0) -> 75 | G8: 4 | L8: =IFERROR(VLOOKUP($O$3, Ejercicios!$A:$B, 2, FALSE) * 0.65,"65%") -> 74.75 | R8: =IFERROR(VLOOKUP($U$3, Ejercicios!$A:$B, 2, FALSE) * 0.65,"65%") -> 74.75 | X8: =IFERROR(VLOOKUP($AA$3, Ejercicios!$A:$B, 2, FALSE) * 0.65,"65%") -> 65% | AC8: =IFERROR(ROUND(VLOOKUP(Configuracion!$I$3 & Configuracion!$I$4, Calculos!$B$19:$L$28, 6, 0)*VLOOKUP(Configuracion!$I$5, Calculos!$A$14:$F$16, 3, 0)*VLOOKUP(ROUND(VLOOKUP(Configuracion!$I$3 & Configuracion!$I$4, Calculos!$B$19:$L$28, 11, 0),0)/100, Ref!$A$2:$K$22, 4, 0), 0),"") | AD8: =IFERROR(VLOOKUP($AG$3, Ejercicios!$A:$B, 2, FALSE) * 0.65,"65%") -> 65% | AI8: =IFERROR(ROUND(VLOOKUP(Configuracion!$I$3 & Configuracion!$I$4, Calculos!$B$19:$L$28, 6, 0)*VLOOKUP(Configuracion!$I$5, Calculos!$A$14:$F$16, 3, 0)*VLOOKUP(ROUND(VLOOKUP(Configuracion!$I$3 & Configuracion!$I$4, Calculos!$B$19:$L$28, 11, 0),0)/100, Ref!$A$2:$K$22, 4, 0), 0),"")
A9: =ROUND(((VLOOKUP(Programacion!$I$2 & Programacion!$I$3, Calculos!$B$3:$L$12, 2, 0)/100)*Programacion!I8*VLOOKUP((Programacion!$I$7+(VLOOKUP(Programacion!$I$2 & Programacion!$I$3, Calculos!$B$3:$L$12, 7, 0)))/100,Ref!A2:K22,5,0)),0)-Entrenamiento!$G$9-Entrenamiento!$S$9-Entrenamiento!$Y$9-Entrenamiento!$AE$9-Entrenamiento!$M$9 -> -5 | B9: =round(((VLOOKUP(Programacion!$I$2 & Programacion!$I$3, Calculos!$B$3:$L$12, 3, 0)/100)*Programacion!$I$8)*VLOOKUP((Programacion!$I$7+(VLOOKUP(Programacion!$I$2 & Programacion!$I$3, Calculos!$B$3:$L$12, 8, 0)))/100,Ref!$A$2:$K$22,5,0),0)-Entrenamiento!$H$9-Entrenamiento!$N$9-Entrenamiento!$T$9-Entrenamiento!$Z$9-Entrenamiento!$AF$9 -> 0 | C9: =round(((VLOOKUP(Programacion!$I$2 & Programacion!$I$3, Calculos!$B$3:$L$12, 4, 0)/100)*Programacion!$I$8)*VLOOKUP((Programacion!$I$7+(VLOOKUP(Programacion!$I$2 & Programacion!$I$3, Calculos!$B$3:$L$12, 9, 0)))/100,Ref!$A$2:$K$22,5,0),0)-Entrenamiento!$I$9-Entrenamiento!$O$9-Entrenamiento!$U$9-Entrenamiento!$AA$9-Entrenamiento!$AG$9 -> 0 | D9: =round(((VLOOKUP(Programacion!$I$2 & Programacion!$I$3, Calculos!$B$3:$L$12, 5, 0)/100)*Programacion!$I$8)*VLOOKUP((Programacion!$I$7+(VLOOKUP(Programacion!$I$2 & Programacion!$I$3, Calculos!$B$3:$L$12, 10, 0)))/100,Ref!$A$2:$K$22,5,0),0)-Entrenamiento!$J$9-Entrenamiento!$P$9-Entrenamiento!$V$9-Entrenamiento!$AB$9-Entrenamiento!$AH$9 -> 0 | E9: =round(((VLOOKUP(Programacion!$I$2 & Programacion!$I$3, Calculos!$B$3:$L$12, 6, 0)/100)*Programacion!$I$8)*VLOOKUP((Programacion!$I$7+(VLOOKUP(Programacion!$I$2 & Programacion!$I$3, Calculos!$B$3:$L$12, 11, 0)))/100,Ref!$A$2:$K$22,5,0),0)-Entrenamiento!$K$9-Entrenamiento!$Q$9-Entrenamiento!$W$9-Entrenamiento!$AC$9-Entrenamiento!$AI$9 -> 0 | F9: =round(IFERROR(VLOOKUP($I$3, Ejercicios!$A:$B, 2, FALSE) * 0.7,"70%") ,0) -> 81 | G9: 4 | H9: 3 | I9: 4 | J9: 3 | K9: 3 | L9: =IFERROR(VLOOKUP($O$3, Ejercicios!$A:$B, 2, FALSE) * 0.7,"70%") -> 80.5 | M9: 6 | N9: 4 | O9: 5 | R9: =IFERROR(VLOOKUP($U$3, Ejercicios!$A:$B, 2, FALSE) * 0.7,"70%") -> 80.5 | S9: 3 | T9: 2 | U9: 3 | V9: 2 | X9: =IFERROR(VLOOKUP($AA$3, Ejercicios!$A:$B, 2, FALSE) * 0.7,"70%") -> 70% | AC9: =IFERROR(ROUND(VLOOKUP(Configuracion!$I$3 & Configuracion!$I$4, Calculos!$B$19:$L$28, 5, 0)*VLOOKUP(Configuracion!$I$5, Calculos!$A$14:$F$16, 3, 0)*VLOOKUP(ROUND(VLOOKUP(Configuracion!$I$3 & Configuracion!$I$4, Calculos!$B$19:$L$28, 11, 0),0)/100, Ref!$A$2:$K$22, 5, 0), 0),"") | AD9: =IFERROR(VLOOKUP($AG$3, Ejercicios!$A:$B, 2, FALSE) * 0.7,"70%") -> 70% | AI9: =IFERROR(ROUND(VLOOKUP(Configuracion!$I$3 & Configuracion!$I$4, Calculos!$B$19:$L$28, 5, 0)*VLOOKUP(Configuracion!$I$5, Calculos!$A$14:$F$16, 3, 0)*VLOOKUP(ROUND(VLOOKUP(Configuracion!$I$3 & Configuracion!$I$4, Calculos!$B$19:$L$28, 11, 0),0)/100, Ref!$A$2:$K$22, 5, 0), 0),"")
A10: =round((VLOOKUP(Programacion!$I$2 & Programacion!$I$3, Calculos!$B$3:$L$12, 2, 0)/100)*Programacion!$I$8*VLOOKUP((Programacion!$I$7+(VLOOKUP(Programacion!$I$2 & Programacion!$I$3, Calculos!$B$3:$L$12, 7, 0)))/100,Ref!A2:K22,6,0),0)-Entrenamiento!$G$10-Entrenamiento!$S$10-Entrenamiento!$Y$10-Entrenamiento!$AE$10-Entrenamiento!$M$10 -> 0 | B10: =ROUND(((VLOOKUP(Programacion!$I$2 & Programacion!$I$3, Calculos!$B$3:$L$12, 3, 0)/100)*Programacion!$I$8)*VLOOKUP((Programacion!$I$7+(VLOOKUP(Programacion!$I$2 & Programacion!$I$3, Calculos!$B$3:$L$12, 8, 0)))/100,Ref!$A$2:$K$22,6,0),0)-Entrenamiento!$H$10-Entrenamiento!$N$10-Entrenamiento!$T$10-Entrenamiento!$Z$10-Entrenamiento!$AF$10 -> 0 | C10: =round(((VLOOKUP(Programacion!$I$2 & Programacion!$I$3, Calculos!$B$3:$L$12, 4, 0)/100)*Programacion!$I$8)*VLOOKUP((Programacion!$I$7+(VLOOKUP(Programacion!$I$2 & Programacion!$I$3, Calculos!$B$3:$L$12, 9, 0)))/100,Ref!$A$2:$K$22,6,0),0)-Entrenamiento!$I$10-Entrenamiento!$O$10-Entrenamiento!$U$10-Entrenamiento!$AA$10-Entrenamiento!$AG$10 -> 0 | D10: =round(((VLOOKUP(Programacion!$I$2 & Programacion!$I$3, Calculos!$B$3:$L$12, 5, 0)/100)*Programacion!$I$8)*VLOOKUP((Programacion!$I$7+(VLOOKUP(Programacion!$I$2 & Programacion!$I$3, Calculos!$B$3:$L$12, 10, 0)))/100,Ref!$A$2:$K$22,6,0),0)-Entrenamiento!$J$10-Entrenamiento!$P$10-Entrenamiento!$V$10-Entrenamiento!$AB$10-Entrenamiento!$AH$10 -> 0 | E10: =round(((VLOOKUP(Programacion!$I$2 & Programacion!$I$3, Calculos!$B$3:$L$12, 6, 0)/100)*Programacion!$I$8)*VLOOKUP((Programacion!$I$7+(VLOOKUP(Programacion!$I$2 & Programacion!$I$3, Calculos!$B$3:$L$12, 11, 0)))/100,Ref!$A$2:$K$22,6,0),0)-Entrenamiento!$K$10-Entrenamiento!$Q$10-Entrenamiento!$W$10-Entrenamiento!$AC$10-Entrenamiento!$AI$10 -> 0 | F10: =round(IFERROR(VLOOKUP($I$3, Ejercicios!$A:$B, 2, FALSE) * 0.75,"75%") ,0) -> 86 | G10: 6 | H10: 6 | I10: 4 | J10: 2 | L10: =IFERROR(VLOOKUP($O$3, Ejercicios!$A:$B, 2, FALSE) * 0.75,"75%") -> 86.25 | M10: 3 | N10: 8 | O10: 6 | P10: 4 | Q10: 3 | R10: =IFERROR(VLOOKUP($U$3, Ejercicios!$A:$B, 2, FALSE) * 0.75,"75%") -> 86.25 | W10: 1 | X10: =IFERROR(VLOOKUP($AA$3, Ejercicios!$A:$B, 2, FALSE) * 0.75,"75%") -> 75% | AC10: =IFERROR(ROUND(VLOOKUP(Configuracion!$I$3 & Configuracion!$I$4, Calculos!$B$19:$L$28, 6, 0)*VLOOKUP(Configuracion!$I$5, Calculos!$A$14:$F$16, 3, 0)*VLOOKUP(ROUND(VLOOKUP(Configuracion!$I$3 & Configuracion!$I$4, Calculos!$B$19:$L$28, 11, 0),0)/100, Ref!$A$2:$K$22, 6, 0), 0),"") | AD10: =IFERROR(VLOOKUP($AG$3, Ejercicios!$A:$B, 2, FALSE) * 0.75,"75%") -> 75% | AI10: =IFERROR(ROUND(VLOOKUP(Configuracion!$I$3 & Configuracion!$I$4, Calculos!$B$19:$L$28, 6, 0)*VLOOKUP(Configuracion!$I$5, Calculos!$A$14:$F$16, 3, 0)*VLOOKUP(ROUND(VLOOKUP(Configuracion!$I$3 & Configuracion!$I$4, Calculos!$B$19:$L$28, 11, 0),0)/100, Ref!$A$2:$K$22, 6, 0), 0),"")
A11: =round((VLOOKUP(Programacion!$I$2 & Programacion!$I$3, Calculos!$B$3:$L$12, 2, 0)/100)*Programacion!$I$8*VLOOKUP((Programacion!$I$7+(VLOOKUP(Programacion!$I$2 & Programacion!$I$3, Calculos!$B$3:$L$12, 7, 0)))/100,Ref!$A$2:$K$22,7,0),0)-Entrenamiento!$G$11-Entrenamiento!$S$11-Entrenamiento!$Y$11-Entrenamiento!$AE$11-Entrenamiento!$M$11 -> 1 | B11: =ROUND(((VLOOKUP(Programacion!$I$2 & Programacion!$I$3, Calculos!$B$3:$L$12, 3, 0)/100)*Programacion!$I$8)*VLOOKUP((Programacion!$I$7+(VLOOKUP(Programacion!$I$2 & Programacion!$I$3, Calculos!$B$3:$L$12, 8, 0)))/100,Ref!$A$2:$K$22,7,0),0)-Entrenamiento!$H$11-Entrenamiento!$N$11-Entrenamiento!$T$11-Entrenamiento!$Z$11-Entrenamiento!$AF$11 -> 0 | C11: =round(((VLOOKUP(Programacion!$I$2 & Programacion!$I$3, Calculos!$B$3:$L$12, 4, 0)/100)*Programacion!$I$8)*VLOOKUP((Programacion!$I$7+(VLOOKUP(Programacion!$I$2 & Programacion!$I$3, Calculos!$B$3:$L$12, 9, 0)))/100,Ref!$A$2:$K$22,7,0),0)-Entrenamiento!$I$11-Entrenamiento!$O$11-Entrenamiento!$U$11-Entrenamiento!$AA$11-Entrenamiento!$AG$11 -> 0 | D11: =round(((VLOOKUP(Programacion!$I$2 & Programacion!$I$3, Calculos!$B$3:$L$12, 5, 0)/100)*Programacion!$I$8)*VLOOKUP((Programacion!$I$7+(VLOOKUP(Programacion!$I$2 & Programacion!$I$3, Calculos!$B$3:$L$12, 10, 0)))/100,Ref!$A$2:$K$22,7,0),0)-Entrenamiento!$J$11-Entrenamiento!$P$11-Entrenamiento!$V$11-Entrenamiento!$AB$11-Entrenamiento!$AH$11 -> 0 | E11: =round(((VLOOKUP(Programacion!$I$2 & Programacion!$I$3, Calculos!$B$3:$L$12, 6, 0)/100)*Programacion!$I$8)*VLOOKUP((Programacion!$I$7+(VLOOKUP(Programacion!$I$2 & Programacion!$I$3, Calculos!$B$3:$L$12, 11, 0)))/100,Ref!$A$2:$K$22,7,0),0)-Entrenamiento!$K$11-Entrenamiento!$Q$11-Entrenamiento!$W$11-Entrenamiento!$AC$11-Entrenamiento!$AI$11 -> 0 | F11: =round(IFERROR(VLOOKUP($I$3, Ejercicios!$A:$B, 2, FALSE) * 0.8,"80%"),0) -> 92 | G11: 2 | H11: 2 | I11: 2 | J11: 3 | K11: 3 | L11: =IFERROR(VLOOKUP($O$3, Ejercicios!$A:$B, 2, FALSE) * 0.8,"80%") -> 92 | M11: 4 | N11: 3 | O11: 4 | P11: 5 | Q11: 4 | R11: =IFERROR(VLOOKUP($U$3, Ejercicios!$A:$B, 2, FALSE) * 0.8,"80%") -> 92 | S11: 1 | T11: 2 | U11: 2 | V11: 2 | X11: =IFERROR(VLOOKUP($AA$3, Ejercicios!$A:$B, 2, FALSE) * 0.8,"80%") -> 80% | AC11: =IFERROR(ROUND(VLOOKUP(Configuracion!$I$3 & Configuracion!$I$4, Calculos!$B$19:$L$28, 6, 0)*VLOOKUP(Configuracion!$I$5, Calculos!$A$14:$F$16, 3, 0)*VLOOKUP(ROUND(VLOOKUP(Configuracion!$I$3 & Configuracion!$I$4, Calculos!$B$19:$L$28, 11, 0),0)/100, Ref!$A$2:$K$22, 7, 0), 0),"") | AD11: =IFERROR(VLOOKUP($AG$3, Ejercicios!$A:$B, 2, FALSE) * 0.8,"80%") -> 80% | AI11: =IFERROR(ROUND(VLOOKUP(Configuracion!$I$3 & Configuracion!$I$4, Calculos!$B$19:$L$28, 6, 0)*VLOOKUP(Configuracion!$I$5, Calculos!$A$14:$F$16, 3, 0)*VLOOKUP(ROUND(VLOOKUP(Configuracion!$I$3 & Configuracion!$I$4, Calculos!$B$19:$L$28, 11, 0),0)/100, Ref!$A$2:$K$22, 7, 0), 0),"")
A12: =round((VLOOKUP(Programacion!$I$2 & Programacion!$I$3, Calculos!$B$3:$L$12, 2, 0)/100)*Programacion!$I$8*VLOOKUP((Programacion!$I$7+(VLOOKUP(Programacion!$I$2 & Programacion!$I$3, Calculos!$B$3:$L$12, 7, 0)))/100,Ref!$A$2:$K$22,8,0),0)-Entrenamiento!$G$12-Entrenamiento!$S$12-Entrenamiento!$Y$12-Entrenamiento!$AE$12-Entrenamiento!$M$12 -> 1 | B12: =ROUND(((VLOOKUP(Programacion!$I$2 & Programacion!$I$3, Calculos!$B$3:$L$12, 3, 0)/100)*Programacion!$I$8)*VLOOKUP((Programacion!$I$7+(VLOOKUP(Programacion!$I$2 & Programacion!$I$3, Calculos!$B$3:$L$12, 8, 0)))/100,Ref!$A$2:$K$22,8,0),0)-Entrenamiento!$H$12-Entrenamiento!$N$12-Entrenamiento!$T$12-Entrenamiento!$Z$12-Entrenamiento!$AF$12 -> 0 | C12: =round(((VLOOKUP(Programacion!$I$2 & Programacion!$I$3, Calculos!$B$3:$L$12, 4, 0)/100)*Programacion!$I$8)*VLOOKUP((Programacion!$I$7+(VLOOKUP(Programacion!$I$2 & Programacion!$I$3, Calculos!$B$3:$L$12, 9, 0)))/100,Ref!$A$2:$K$22,8,0),0)-Entrenamiento!$I$12-Entrenamiento!$O$12-Entrenamiento!$U$12-Entrenamiento!$AA$12-Entrenamiento!$AG$12 -> 0 | D12: =round(((VLOOKUP(Programacion!$I$2 & Programacion!$I$3, Calculos!$B$3:$L$12, 5, 0)/100)*Programacion!$I$8)*VLOOKUP((Programacion!$I$7+(VLOOKUP(Programacion!$I$2 & Programacion!$I$3, Calculos!$B$3:$L$12, 10, 0)))/100,Ref!$A$2:$K$22,8,0),0)-Entrenamiento!$J$12-Entrenamiento!$P$12-Entrenamiento!$V$12-Entrenamiento!$AB$12-Entrenamiento!$AH$12 -> 0 | E12: =round(((VLOOKUP(Programacion!$I$2 & Programacion!$I$3, Calculos!$B$3:$L$12, 6, 0)/100)*Programacion!$I$8)*VLOOKUP((Programacion!$I$7+(VLOOKUP(Programacion!$I$2 & Programacion!$I$3, Calculos!$B$3:$L$12, 11, 0)))/100,Ref!$A$2:$K$22,8,0),0)-Entrenamiento!$K$12-Entrenamiento!$Q$12-Entrenamiento!$W$12-Entrenamiento!$AC$12-Entrenamiento!$AI$12 -> 0 | F12: =round(IFERROR(VLOOKUP($I$3, Ejercicios!$A:$B, 2, FALSE) * 0.85,"85%") ,0) -> 98 | G12: 1 | H12: 2 | I12: 2 | J12: 5 | K12: 2 | L12: =IFERROR(VLOOKUP($O$3, Ejercicios!$A:$B, 2, FALSE) * 0.85,"85%") -> 97.75 | M12: 3 | N12: 2 | O12: 1 | P12: 3 | Q12: 2 | R12: =IFERROR(VLOOKUP($U$3, Ejercicios!$A:$B, 2, FALSE) * 0.85,"85%") -> 97.75 | S12: 1 | T12: 1 | U12: 2 | W12: 1 | X12: =IFERROR(VLOOKUP($AA$3, Ejercicios!$A:$B, 2, FALSE) * 0.85,"85%") -> 85% | AC12: =IFERROR(ROUND(VLOOKUP(Configuracion!$I$3 & Configuracion!$I$4, Calculos!$B$19:$L$28, 6, 0)*VLOOKUP(Configuracion!$I$5, Calculos!$A$14:$F$16, 3, 0)*VLOOKUP(ROUND(VLOOKUP(Configuracion!$I$3 & Configuracion!$I$4, Calculos!$B$19:$L$28, 11, 0),0)/100, Ref!$A$2:$K$22, 8, 0), 0),"") | AD12: =IFERROR(VLOOKUP($AG$3, Ejercicios!$A:$B, 2, FALSE) * 0.85,"85%") -> 85% | AI12: =IFERROR(ROUND(VLOOKUP(Configuracion!$I$3 & Configuracion!$I$4, Calculos!$B$19:$L$28, 6, 0)*VLOOKUP(Configuracion!$I$5, Calculos!$A$14:$F$16, 3, 0)*VLOOKUP(ROUND(VLOOKUP(Configuracion!$I$3 & Configuracion!$I$4, Calculos!$B$19:$L$28, 11, 0),0)/100, Ref!$A$2:$K$22, 8, 0), 0),"")
A13: =round(((VLOOKUP(Programacion!$I$2 & Programacion!$I$3, Calculos!$B$3:$L$12, 2, 0)/100)*Programacion!$I$8)*VLOOKUP((Programacion!$I$7+(VLOOKUP(Programacion!$I$2 & Programacion!$I$3, Calculos!$B$3:$L$12, 7, 0)))/100,Ref!$A$2:$K$22,9,0),0)-Entrenamiento!$G$13-Entrenamiento!$S$13-Entrenamiento!$Y$13-Entrenamiento!$AE$13-Entrenamiento!$M$13 -> 0 | B13: =ROUND(((VLOOKUP(Programacion!$I$2 & Programacion!$I$3, Calculos!$B$3:$L$12, 3, 0)/100)*Programacion!$I$8)*VLOOKUP((Programacion!$I$7+(VLOOKUP(Programacion!$I$2 & Programacion!$I$3, Calculos!$B$3:$L$12, 8, 0)))/100,Ref!$A$2:$K$22,9,0),0)-Entrenamiento!$H$13-Entrenamiento!$N$13-Entrenamiento!$T$13-Entrenamiento!$Z$13-Entrenamiento!$AF$13 -> 0 | C13: =round(((VLOOKUP(Programacion!$I$2 & Programacion!$I$3, Calculos!$B$3:$L$12, 4, 0)/100)*Programacion!$I$8)*VLOOKUP((Programacion!$I$7+(VLOOKUP(Programacion!$I$2 & Programacion!$I$3, Calculos!$B$3:$L$12, 9, 0)))/100,Ref!$A$2:$K$22,9,0),0)-Entrenamiento!$I$13-Entrenamiento!$O$13-Entrenamiento!$U$13-Entrenamiento!$AA$13-Entrenamiento!$AG$13 -> 0 | D13: =round(((VLOOKUP(Programacion!$I$2 & Programacion!$I$3, Calculos!$B$3:$L$12, 5, 0)/100)*Programacion!$I$8)*VLOOKUP((Programacion!$I$7+(VLOOKUP(Programacion!$I$2 & Programacion!$I$3, Calculos!$B$3:$L$12, 10, 0)))/100,Ref!$A$2:$K$22,9,0),0)-Entrenamiento!$J$13-Entrenamiento!$P$13-Entrenamiento!$V$13-Entrenamiento!$AB$13-Entrenamiento!$AH$13 -> 0 | E13: =round(((VLOOKUP(Programacion!$I$2 & Programacion!$I$3, Calculos!$B$3:$L$12, 6, 0)/100)*Programacion!$I$8)*VLOOKUP((Programacion!$I$7+(VLOOKUP(Programacion!$I$2 & Programacion!$I$3, Calculos!$B$3:$L$12, 11, 0)))/100,Ref!$A$2:$K$22,9,0),0)-Entrenamiento!$K$13-Entrenamiento!$Q$13-Entrenamiento!$W$13-Entrenamiento!$AC$13-Entrenamiento!$AI$13 -> 0 | F13: =round(IFERROR(VLOOKUP($I$3, Ejercicios!$A:$B, 2, FALSE) * 0.9,"90%"),0) -> 104 | K13: 1 | L13: =round(IFERROR(VLOOKUP($O$3, Ejercicios!$A:$B, 2, FALSE) * 0.9,"90%"),0) -> 104 | R13: =round(IFERROR(VLOOKUP($U$3, Ejercicios!$A:$B, 2, FALSE) * 0.9,"90%"),0) -> 104 | S13: 2 | T13: 2 | U13: 3 | V13: 3 | W13: 1 | X13: =IFERROR(VLOOKUP($AA$3, Ejercicios!$A:$B, 2, FALSE) * 0.9,"90%") -> 90% | AC13: =IFERROR(ROUND(VLOOKUP(Configuracion!$I$3 & Configuracion!$I$4, Calculos!$B$19:$L$28, 6, 0)*VLOOKUP(Configuracion!$I$5, Calculos!$A$14:$F$16, 3, 0)*VLOOKUP(ROUND(VLOOKUP(Configuracion!$I$3 & Configuracion!$I$4, Calculos!$B$19:$L$28, 11, 0),0)/100, Ref!$A$2:$K$22, 9, 0), 0),"") | AD13: =IFERROR(VLOOKUP($AG$3, Ejercicios!$A:$B, 2, FALSE) * 0.9,"90%") -> 90% | AI13: =IFERROR(ROUND(VLOOKUP(Configuracion!$I$3 & Configuracion!$I$4, Calculos!$B$19:$L$28, 6, 0)*VLOOKUP(Configuracion!$I$5, Calculos!$A$14:$F$16, 3, 0)*VLOOKUP(ROUND(VLOOKUP(Configuracion!$I$3 & Configuracion!$I$4, Calculos!$B$19:$L$28, 11, 0),0)/100, Ref!$A$2:$K$22, 9, 0), 0),"")
A14: =round(((VLOOKUP(Programacion!$I$2 & Programacion!$I$3, Calculos!$B$3:$L$12, 2, 0)/100)*Programacion!$I$8)*VLOOKUP((Programacion!$I$7+(VLOOKUP(Programacion!$I$2 & Programacion!$I$3, Calculos!$B$3:$L$12, 7, 0)))/100,Ref!$A$2:$K$22,10,0),0)-Entrenamiento!$G$14-Entrenamiento!$S$14-Entrenamiento!$Y$14-Entrenamiento!$AE$14-Entrenamiento!$M$14 -> 0 | B14: =ROUND(((VLOOKUP(Programacion!$I$2 & Programacion!$I$3, Calculos!$B$3:$L$12, 3, 0)/100)*Programacion!$I$8)*VLOOKUP((Programacion!$I$7+(VLOOKUP(Programacion!$I$2 & Programacion!$I$3, Calculos!$B$3:$L$12, 8, 0)))/100,Ref!$A$2:$K$22,10,0),0)-Entrenamiento!$H$14-Entrenamiento!$N$14-Entrenamiento!$T$14-Entrenamiento!$Z$14-Entrenamiento!$AF$14 -> 0 | C14: =round(((VLOOKUP(Programacion!$I$2 & Programacion!$I$3, Calculos!$B$3:$L$12, 4, 0)/100)*Programacion!$I$8)*VLOOKUP((Programacion!$I$7+(VLOOKUP(Programacion!$I$2 & Programacion!$I$3, Calculos!$B$3:$L$12, 9, 0)))/100,Ref!$A$2:$K$22,10,0),0)-Entrenamiento!$I$14-Entrenamiento!$O$14-Entrenamiento!$U$14-Entrenamiento!$AA$14-Entrenamiento!$AG$14 -> 0 | D14: =round(((VLOOKUP(Programacion!$I$2 & Programacion!$I$3, Calculos!$B$3:$L$12, 5, 0)/100)*Programacion!$I$8)*VLOOKUP((Programacion!$I$7+(VLOOKUP(Programacion!$I$2 & Programacion!$I$3, Calculos!$B$3:$L$12, 10, 0)))/100,Ref!$A$2:$K$22,10,0),0)-Entrenamiento!$J$14-Entrenamiento!$P$14-Entrenamiento!$V$14-Entrenamiento!$AB$14-Entrenamiento!$AH$14 -> 0 | E14: =round(((VLOOKUP(Programacion!$I$2 & Programacion!$I$3, Calculos!$B$3:$L$12, 6, 0)/100)*Programacion!$I$8)*VLOOKUP((Programacion!$I$7+(VLOOKUP(Programacion!$I$2 & Programacion!$I$3, Calculos!$B$3:$L$12, 11, 0)))/100,Ref!$A$2:$K$22,10,0),0)-Entrenamiento!$K$14-Entrenamiento!$Q$14-Entrenamiento!$W$14-Entrenamiento!$AC$14-Entrenamiento!$AI$14 -> 0 | F14: =round(IFERROR(VLOOKUP($I$3, Ejercicios!$A:$B, 2, FALSE) * 0.95,"95%") ,0) -> 109 | L14: =IFERROR(VLOOKUP($O$3, Ejercicios!$A:$B, 2, FALSE) * 0.95,"95%") -> 109.25 | Q14: =IFERROR(ROUND(VLOOKUP(Configuracion!$I$3 & Configuracion!$I$4, Calculos!$B$19:$L$28, 6, 0)*VLOOKUP(Configuracion!$I$5, Calculos!$A$14:$F$16, 3, 0)*VLOOKUP(ROUND(VLOOKUP(Configuracion!$I$3 & Configuracion!$I$4, Calculos!$B$19:$L$28, 11, 0),0)/100, Ref!$A$2:$K$22, 10, 0), 0),"") | R14: =IFERROR(VLOOKUP($U$3, Ejercicios!$A:$B, 2, FALSE) * 0.95,"95%") -> 109.25 | W14: 1 | X14: =IFERROR(VLOOKUP($AA$3, Ejercicios!$A:$B, 2, FALSE) * 0.95,"95%") -> 95% | AC14: =IFERROR(ROUND(VLOOKUP(Configuracion!$I$3 & Configuracion!$I$4, Calculos!$B$19:$L$28, 6, 0)*VLOOKUP(Configuracion!$I$5, Calculos!$A$14:$F$16, 3, 0)*VLOOKUP(ROUND(VLOOKUP(Configuracion!$I$3 & Configuracion!$I$4, Calculos!$B$19:$L$28, 11, 0),0)/100, Ref!$A$2:$K$22, 10, 0), 0),"") | AD14: =IFERROR(VLOOKUP($AG$3, Ejercicios!$A:$B, 2, FALSE) * 0.95,"95%") -> 95% | AI14: =IFERROR(ROUND(VLOOKUP(Configuracion!$I$3 & Configuracion!$I$4, Calculos!$B$19:$L$28, 6, 0)*VLOOKUP(Configuracion!$I$5, Calculos!$A$14:$F$16, 3, 0)*VLOOKUP(ROUND(VLOOKUP(Configuracion!$I$3 & Configuracion!$I$4, Calculos!$B$19:$L$28, 11, 0),0)/100, Ref!$A$2:$K$22, 10, 0), 0),"")
A15: =round(((VLOOKUP(Programacion!$I$2 & Programacion!$I$3, Calculos!$B$3:$L$12, 2, 0)/100)*Programacion!$I$8)*VLOOKUP((Programacion!$I$7+(VLOOKUP(Programacion!$I$2 & Programacion!$I$3, Calculos!$B$3:$L$12, 7, 0)))/100,Ref!$A$2:$K$22,11,0),0)-Entrenamiento!$G$15-Entrenamiento!$S$15-Entrenamiento!$Y$15-Entrenamiento!$AE$15-Entrenamiento!$M$15 -> 0 | B15: =ROUND(((VLOOKUP(Programacion!$I$2 & Programacion!$I$3, Calculos!$B$3:$L$12, 3, 0)/100)*Programacion!$I$8)*VLOOKUP((Programacion!$I$7+(VLOOKUP(Programacion!$I$2 & Programacion!$I$3, Calculos!$B$3:$L$12, 8, 0)))/100,Ref!$A$2:$K$22,11,0),0)-Entrenamiento!$H$15-Entrenamiento!$N$15-Entrenamiento!$T$15-Entrenamiento!$Z$15-Entrenamiento!$AF$15 -> 0 | C15: =round(((VLOOKUP(Programacion!$I$2 & Programacion!$I$3, Calculos!$B$3:$L$12, 4, 0)/100)*Programacion!$I$8)*VLOOKUP((Programacion!$I$7+(VLOOKUP(Programacion!$I$2 & Programacion!$I$3, Calculos!$B$3:$L$12, 9, 0)))/100,Ref!$A$2:$K$22,11,0),0)-Entrenamiento!$I$15-Entrenamiento!$O$15-Entrenamiento!$U$15-Entrenamiento!$AA$15-Entrenamiento!$AG$15 -> 0 | D15: =round(((VLOOKUP(Programacion!$I$2 & Programacion!$I$3, Calculos!$B$3:$L$12, 5, 0)/100)*Programacion!$I$8)*VLOOKUP((Programacion!$I$7+(VLOOKUP(Programacion!$I$2 & Programacion!$I$3, Calculos!$B$3:$L$12, 10, 0)))/100,Ref!$A$2:$K$22,11,0),0)-Entrenamiento!$J$15-Entrenamiento!$P$15-Entrenamiento!$V$15-Entrenamiento!$AB$15-Entrenamiento!$AH$15 -> 0 | E15: =round(((VLOOKUP(Programacion!$I$2 & Programacion!$I$3, Calculos!$B$3:$L$12, 6, 0)/100)*Programacion!$I$8)*VLOOKUP((Programacion!$I$7+(VLOOKUP(Programacion!$I$2 & Programacion!$I$3, Calculos!$B$3:$L$12, 11, 0)))/100,Ref!$A$2:$K$22,11,0),0)-Entrenamiento!$K$15-Entrenamiento!$Q$15-Entrenamiento!$W$15-Entrenamiento!$AC$15-Entrenamiento!$AI$15 -> 0 | F15: =round(IFERROR(VLOOKUP($I$3, Ejercicios!$A:$B, 2, FALSE) * 1,"100%") ,0) -> 115 | K15: =IFERROR(ROUND(VLOOKUP(Configuracion!$I$3 & Configuracion!$I$4, Calculos!$B$19:$L$28, 6, 0)*VLOOKUP(Configuracion!$I$5, Calculos!$A$14:$F$16, 3, 0)*VLOOKUP(ROUND(VLOOKUP(Configuracion!$I$3 & Configuracion!$I$4, Calculos!$B$19:$L$28, 11, 0),0)/100, Ref!$A$2:$K$22, 11, 0), 0),"") | L15: =IFERROR(VLOOKUP($O$3, Ejercicios!$A:$B, 2, FALSE) * 1,"100%") -> 115 | Q15: =IFERROR(ROUND(VLOOKUP(Configuracion!$I$3 & Configuracion!$I$4, Calculos!$B$19:$L$28, 6, 0)*VLOOKUP(Configuracion!$I$5, Calculos!$A$14:$F$16, 3, 0)*VLOOKUP(ROUND(VLOOKUP(Configuracion!$I$3 & Configuracion!$I$4, Calculos!$B$19:$L$28, 11, 0),0)/100, Ref!$A$2:$K$22, 11, 0), 0),"") | R15: =IFERROR(VLOOKUP($U$3, Ejercicios!$A:$B, 2, FALSE) * 1,"100%") -> 115 | X15: =IFERROR(VLOOKUP($AA$3, Ejercicios!$A:$B, 2, FALSE) * 1,"100%") -> 100% | AC15: =IFERROR(ROUND(VLOOKUP(Configuracion!$I$3 & Configuracion!$I$4, Calculos!$B$19:$L$28, 6, 0)*VLOOKUP(Configuracion!$I$5, Calculos!$A$14:$F$16, 3, 0)*VLOOKUP(ROUND(VLOOKUP(Configuracion!$I$3 & Configuracion!$I$4, Calculos!$B$19:$L$28, 11, 0),0)/100, Ref!$A$2:$K$22, 11, 0), 0),"") | AD15: =IFERROR(VLOOKUP($AG$3, Ejercicios!$A:$B, 2, FALSE) * 1,"100%") -> 100% | AI15: =IFERROR(ROUND(VLOOKUP(Configuracion!$I$3 & Configuracion!$I$4, Calculos!$B$19:$L$28, 6, 0)*VLOOKUP(Configuracion!$I$5, Calculos!$A$14:$F$16, 3, 0)*VLOOKUP(ROUND(VLOOKUP(Configuracion!$I$3 & Configuracion!$I$4, Calculos!$B$19:$L$28, 11, 0),0)/100, Ref!$A$2:$K$22, 11, 0), 0),"")
I16: Sentadilla | O16: Tiron de cargada | U16: Sentadilla
A17: Fuerza | B17: Fuerza | C17: Fuerza | D17: Fuerza | E17: Fuerza | F17: KG | G17: DIA 1 | H17: DIA 1 | I17: DIA 1 | J17: DIA 1 | K17: DIA 1 | L17: KG | M17: DIA 2 | N17: DIA 2 | O17: DIA 2 | P17: DIA 2 | Q17: DIA 2 | R17: KG | S17: DIA 3 | T17: DIA 3 | U17: DIA 3 | V17: DIA 3 | W17: DIA 3 | X17: KG | Y17: DIA 4 | Z17: DIA 4 | AA17: DIA 4 | AB17: DIA 4 | AC17: DIA 4 | AD17: KG | AE17: DIA 5 | AF17: DIA 5 | AG17: DIA 5 | AH17: DIA 5 | AI17: DIA 5
F18: Repeticiones | G18: =ROUND(VLOOKUP(Programacion!$I$4, Calculos!$A$14:$F$16, 2, 0)*(VLOOKUP(Programacion!$I$2 & Programacion!$I$3, Calculos!$B$3:$L$12, 2, 0)/100)*Programacion!$I$13,0)-SUM(Entrenamiento!$G$19:$G$28) -> -9 | H18: =ROUND(VLOOKUP(Programacion!$I$4, Calculos!$A$14:$F$16, 2, 0)*(VLOOKUP(Programacion!$I$2 & Programacion!$I$3, Calculos!$B$3:$L$12, 3, 0)/100)*Programacion!$I$13,0)-SUM(Entrenamiento!$H$19:$H$28) -> 0 | I18: =ROUND(VLOOKUP(Programacion!$I$4, Calculos!$A$14:$F$16, 2, 0)*(VLOOKUP(Programacion!$I$2 & Programacion!$I$3, Calculos!$B$3:$L$12, 4, 0)/100)*Programacion!$I$13,0)-SUM(Entrenamiento!$I$19:$I$28) -> 0 | J18: =ROUND(VLOOKUP(Programacion!$I$4, Calculos!$A$14:$F$16, 2, 0)*(VLOOKUP(Programacion!$I$2 & Programacion!$I$3, Calculos!$B$3:$L$12, 5, 0)/100)*Programacion!$I$13,0)-SUM(Entrenamiento!$J$19:$J$28) -> -1 | K18: =ROUND(VLOOKUP(Programacion!$I$4, Calculos!$A$14:$F$16, 2, 0)*(VLOOKUP(Programacion!$I$2 & Programacion!$I$3, Calculos!$B$3:$L$12, 6, 0)/100)*Programacion!$I$13,0)-SUM(Entrenamiento!$K$19:$K$28) -> 0 | L18: Repeticiones | M18: =ROUND(VLOOKUP(Programacion!$I$4, Calculos!$A$14:$F$16, 3, 0)*(VLOOKUP(Programacion!$I$2 & Programacion!$I$3, Calculos!$B$3:$L$12, 2, 0)/100)*Programacion!$I$13,0)-SUM(Entrenamiento!$M$19:$M$28) -> 10 | N18: =ROUND(VLOOKUP(Programacion!$I$4, Calculos!$A$14:$F$16, 3, 0)*(VLOOKUP(Programacion!$I$2 & Programacion!$I$3, Calculos!$B$3:$L$12, 3, 0)/100)*Programacion!$I$13,0)-SUM(Entrenamiento!$N$19:$N$28) -> 0 | O18: =ROUND(VLOOKUP(Programacion!$I$4, Calculos!$A$14:$F$16, 3, 0)*(VLOOKUP(Programacion!$I$2 & Programacion!$I$3, Calculos!$B$3:$L$12, 4, 0)/100)*Programacion!$I$13,0)-SUM(Entrenamiento!$O$19:$O$28) -> 1 | P18: =ROUND(VLOOKUP(Programacion!$I$4, Calculos!$A$14:$F$16, 3, 0)*(VLOOKUP(Programacion!$I$2 & Programacion!$I$3, Calculos!$B$3:$L$12, 5, 0)/100)*Programacion!$I$13,0)-SUM(Entrenamiento!$P$19:$P$28) -> 0 | Q18: =ROUND(VLOOKUP(Programacion!$I$4, Calculos!$A$14:$F$16, 3, 0)*(VLOOKUP(Programacion!$I$2 & Programacion!$I$3, Calculos!$B$3:$L$12, 6, 0)/100)*Programacion!$I$13,0)-SUM(Entrenamiento!$Q$19:$Q$28) -> -1 | S18: =ROUND(VLOOKUP(Programacion!$I$4, Calculos!$A$14:$F$16, 4, 0)*(VLOOKUP(Programacion!$I$2 & Programacion!$I$3, Calculos!$B$3:$L$12, 2, 0)/100)*Programacion!$I$13,0)-SUM(Entrenamiento!$S$19:$S$28) -> 1 | T18: =ROUND(VLOOKUP(Programacion!$I$4, Calculos!$A$14:$F$16, 4, 0)*(VLOOKUP(Programacion!$I$2 & Programacion!$I$3, Calculos!$B$3:$L$12, 3, 0)/100)*Programacion!$I$13,0)-SUM(Entrenamiento!$T$19:$T$28) -> 0 | U18: =ROUND(VLOOKUP(Programacion!$I$4, Calculos!$A$14:$F$16, 4, 0)*(VLOOKUP(Programacion!$I$2 & Programacion!$I$3, Calculos!$B$3:$L$12, 4, 0)/100)*Programacion!$I$13,0)-SUM(Entrenamiento!$U$19:$U$28) -> 0 | V18: =ROUND(VLOOKUP(Programacion!$I$4, Calculos!$A$14:$F$16, 4, 0)*(VLOOKUP(Programacion!$I$2 & Programacion!$I$3, Calculos!$B$3:$L$12, 5, 0)/100)*Programacion!$I$13,0)-SUM(Entrenamiento!$V$19:$V$28) -> 0 | W18: =ROUND(VLOOKUP(Programacion!$I$4, Calculos!$A$14:$F$16, 4, 0)*(VLOOKUP(Programacion!$I$2 & Programacion!$I$3, Calculos!$B$3:$L$12, 6, 0)/100)*Programacion!$I$13,0)-SUM(Entrenamiento!$W$19:$W$28) -> 0 | AC18: =ROUND(VLOOKUP(Programacion!$I$4, Calculos!$A$14:$F$16, 5, 0)*(VLOOKUP(Programacion!$I$2 & Programacion!$I$3, Calculos!$B$3:$L$12, 6, 0)/100)*Programacion!$I$13,0)-SUM(Entrenamiento!$AC$19:$AC$28) -> 0 | AE18: =ROUND(VLOOKUP(Programacion!$I$4, Calculos!$A$14:$F$16, 6, 0)*(VLOOKUP(Programacion!$I$2 & Programacion!$I$3, Calculos!$B$3:$L$12, 2, 0)/100)*Programacion!$I$13,0)-SUM(Entrenamiento!$AE$19:$AE$28) -> 0 | AF18: =ROUND(VLOOKUP(Programacion!$I$4, Calculos!$A$14:$F$16, 6, 0)*(VLOOKUP(Programacion!$I$2 & Programacion!$I$3, Calculos!$B$3:$L$12, 3, 0)/100)*Programacion!$I$13,0)-SUM(Entrenamiento!$AF$19:$AF$28) -> 0 | AG18: =ROUND(VLOOKUP(Programacion!$I$4, Calculos!$A$14:$F$16, 6, 0)*(VLOOKUP(Programacion!$I$2 & Programacion!$I$3, Calculos!$B$3:$L$12, 4, 0)/100)*Programacion!$I$13,0)-SUM(Entrenamiento!$AG$19:$AG$28) -> 0 | AH18: =ROUND(VLOOKUP(Programacion!$I$4, Calculos!$A$14:$F$16, 6, 0)*(VLOOKUP(Programacion!$I$2 & Programacion!$I$3, Calculos!$B$3:$L$12, 5, 0)/100)*Programacion!$I$13,0)-SUM(Entrenamiento!$AH$19:$AH$28) -> 0 | AI18: =ROUND(VLOOKUP(Programacion!$I$4, Calculos!$A$14:$F$16, 6, 0)*(VLOOKUP(Programacion!$I$2 & Programacion!$I$3, Calculos!$B$3:$L$12, 6, 0)/100)*Programacion!$I$13,0)-SUM(Entrenamiento!$AI$19:$AO$28) -> 0
A19: =A20 -> 0 | B19: =B20 -> 0 | C19: =C20 -> 0 | D19: =D20 -> 0 | E19: =E20 -> 0 | F19: =IFERROR(VLOOKUP($I$16, Ejercicios!$A:$B, 2, FALSE) * 0.55,"55%") -> 77 | G19: 3 | H19: 5 | I19: 5 | K19: 3 | L19: =IFERROR(VLOOKUP($O$16, Ejercicios!$A:$B, 2, FALSE) * 0.55,"55%") -> 99 | N19: 5 | O19: 6 | P19: 6 | Q19: 7 | R19: =IFERROR(VLOOKUP($U$16, Ejercicios!$A:$B, 2, FALSE) * 0.55,"55%") -> 77 | U19: 5 | X19: =IFERROR(VLOOKUP($AA$16, Ejercicios!$A:$B, 2, FALSE) * 0.55,"55%") -> 55% | AC19: =IFERROR(ROUND(VLOOKUP(Configuracion!$I$3 & Configuracion!$I$4, Calculos!$B$19:$L$28, 6, 0)*VLOOKUP(Configuracion!$I$5, Calculos!$A$14:$F$16, 3, 0)*VLOOKUP(ROUND(VLOOKUP(Configuracion!$I$3 & Configuracion!$I$4, Calculos!$B$19:$L$28, 11, 0),0)/100, Ref!$A$2:$K$22, 2, 0), ""),"") | AD19: =IFERROR(VLOOKUP($AG$16, Ejercicios!$A:$B, 2, FALSE) * 0.55,"55%") -> 55% | AI19: =IFERROR(ROUND(VLOOKUP(Configuracion!$I$3 & Configuracion!$I$4, Calculos!$B$19:$L$28, 6, 0)*VLOOKUP(Configuracion!$I$5, Calculos!$A$14:$F$16, 3, 0)*VLOOKUP(ROUND(VLOOKUP(Configuracion!$I$3 & Configuracion!$I$4, Calculos!$B$19:$L$28, 11, 0),0)/100, Ref!$A$2:$K$22, 2, 0), ""),"")
A20: =round(((VLOOKUP(Programacion!$I$2 & Programacion!$I$3, Calculos!$B$3:$L$12, 2, 0)/100)*Programacion!$I$13)*VLOOKUP((Programacion!$I$12+(VLOOKUP(Programacion!$I$2 & Programacion!$I$3, Calculos!$B$3:$L$12, 7, 0)))/100,Ref!$A$2:$K$22,2,0),0)+round(((VLOOKUP(Programacion!$I$2 & Programacion!$I$3, Calculos!$B$3:$L$12, 2, 0)/100)*Programacion!$I$13)*VLOOKUP((Programacion!$I$12+(VLOOKUP(Programacion!$I$2 & Programacion!$I$3, Calculos!$B$3:$L$12, 7, 0)))/100,Ref!$A$2:$K$22,4,0),0)+round(((VLOOKUP(Programacion!$I$2 & Programacion!$I$3, Calculos!$B$3:$L$12, 2, 0)/100)*Programacion!$I$13)*VLOOKUP((Programacion!$I$12+(VLOOKUP(Programacion!$I$2 & Programacion!$I$3, Calculos!$B$3:$L$12, 7, 0)))/100,Ref!$A$2:$K$22,3,0),0) -SUM(Entrenamiento!$G$19:G21)-SUM(Entrenamiento!$M$19:$M$21)-SUM(Entrenamiento!$S$19:$S$21)-SUM(Entrenamiento!$Y$19:$Y$21)-SUM(Entrenamiento!$AE$19:$AE$21) -> 0 | B20: =round(((VLOOKUP(Programacion!$I$2 & Programacion!$I$3, Calculos!$B$3:$L$12, 3, 0)/100)*Programacion!$I$13)*VLOOKUP((Programacion!$I$12+(VLOOKUP(Programacion!$I$2 & Programacion!$I$3, Calculos!$B$3:$L$12, 8, 0)))/100,Ref!$A$2:$K$22,2,0),0)+round(((VLOOKUP(Programacion!$I$2 & Programacion!$I$3, Calculos!$B$3:$L$12, 3, 0)/100)*Programacion!$I$13)*VLOOKUP((Programacion!$I$12+(VLOOKUP(Programacion!$I$2 & Programacion!$I$3, Calculos!$B$3:$L$12, 8, 0)))/100,Ref!$A$2:$K$22,3,0),0)+round(((VLOOKUP(Programacion!$I$2 & Programacion!$I$3, Calculos!$B$3:$L$12, 3, 0)/100)*Programacion!$I$13)*VLOOKUP((Programacion!$I$12+(VLOOKUP(Programacion!$I$2 & Programacion!$I$3, Calculos!$B$3:$L$12, 8, 0)))/100,Ref!$A$2:$K$22,4,0),0)-SUM(Entrenamiento!$H$19:H21)-SUM(Entrenamiento!$N$19:$N$21)-SUM(Entrenamiento!$T$19:$T$21)-SUM(Entrenamiento!$Z$19:$Z$21)-SUM(Entrenamiento!$AF$19:$AF$21) -> 0 | C20: =round(((VLOOKUP(Programacion!$I$2 & Programacion!$I$3, Calculos!$B$3:$L$12, 4, 0)/100)*Programacion!$I$13)*VLOOKUP((Programacion!$I$12+(VLOOKUP(Programacion!$I$2 & Programacion!$I$3, Calculos!$B$3:$L$12, 9, 0)))/100,Ref!$A$2:$K$22,2,0),0)+round(((VLOOKUP(Programacion!$I$2 & Programacion!$I$3, Calculos!$B$3:$L$12, 4, 0)/100)*Programacion!$I$13)*VLOOKUP((Programacion!$I$12+(VLOOKUP(Programacion!$I$2 & Programacion!$I$3, Calculos!$B$3:$L$12, 9, 0)))/100,Ref!$A$2:$K$22,3,0),0)+round(((VLOOKUP(Programacion!$I$2 & Programacion!$I$3, Calculos!$B$3:$L$12, 4, 0)/100)*Programacion!$I$13)*VLOOKUP((Programacion!$I$12+(VLOOKUP(Programacion!$I$2 & Programacion!$I$3, Calculos!$B$3:$L$12, 9, 0)))/100,Ref!$A$2:$K$22,4,0),0)-SUM(Entrenamiento!$I$19:$I$21)-SUM(Entrenamiento!$O$19:O21)-SUM(Entrenamiento!$U$19:$U$21)-SUM(Entrenamiento!$AA$19:$AA$21)-SUM(Entrenamiento!$AG$19:$AG$21) -> 0 | D20: =round(((VLOOKUP(Programacion!$I$2 & Programacion!$I$3, Calculos!$B$3:$L$12, 5, 0)/100)*Programacion!$I$13)*VLOOKUP((Programacion!$I$12+(VLOOKUP(Programacion!$I$2 & Programacion!$I$3, Calculos!$B$3:$L$12, 10, 0)))/100,Ref!$A$2:$K$22,2,0),0)+round(((VLOOKUP(Programacion!$I$2 & Programacion!$I$3, Calculos!$B$3:$L$12, 5, 0)/100)*Programacion!$I$13)*VLOOKUP((Programacion!$I$12+(VLOOKUP(Programacion!$I$2 & Programacion!$I$3, Calculos!$B$3:$L$12, 10, 0)))/100,Ref!$A$2:$K$22,3,0),0)+round(((VLOOKUP(Programacion!$I$2 & Programacion!$I$3, Calculos!$B$3:$L$12, 5, 0)/100)*Programacion!$I$13)*VLOOKUP((Programacion!$I$12+(VLOOKUP(Programacion!$I$2 & Programacion!$I$3, Calculos!$B$3:$L$12, 10, 0)))/100,Ref!$A$2:$K$22,4,0),0)-SUM(Entrenamiento!$J$19:J21)-SUM(Entrenamiento!$P$19:$P$21)-SUM(Entrenamiento!$V$19:$V$21)-SUM(Entrenamiento!$AB$19:ABZ$21)-SUM(Entrenamiento!$AH$19:$AH$21) -> 0 | E20: =round(((VLOOKUP(Programacion!$I$2 & Programacion!$I$3, Calculos!$B$3:$L$12, 6, 0)/100)*Programacion!$I$13)*VLOOKUP((Programacion!$I$12+(VLOOKUP(Programacion!$I$2 & Programacion!$I$3, Calculos!$B$3:$L$12, 11, 0)))/100,Ref!$A$2:$K$22,2,0),0)+round(((VLOOKUP(Programacion!$I$2 & Programacion!$I$3, Calculos!$B$3:$L$12, 6, 0)/100)*Programacion!$I$13)*VLOOKUP((Programacion!$I$12+(VLOOKUP(Programacion!$I$2 & Programacion!$I$3, Calculos!$B$3:$L$12, 11, 0)))/100,Ref!$A$2:$K$22,3,0),0)+round(((VLOOKUP(Programacion!$I$2 & Programacion!$I$3, Calculos!$B$3:$L$12, 6, 0)/100)*Programacion!$I$13)*VLOOKUP((Programacion!$I$12+(VLOOKUP(Programacion!$I$2 & Programacion!$I$3, Calculos!$B$3:$L$12, 11, 0)))/100,Ref!$A$2:$K$22,4,0),0)-SUM(Entrenamiento!$K$19:K21)-SUM(Entrenamiento!$Q$19:$Q$21)-SUM(Entrenamiento!$W$19:$W$21)-SUM(Entrenamiento!AC$19:$AC$21)-SUM(Entrenamiento!$AI$19:$AI$21) -> 0 | F20: =IFERROR(VLOOKUP($I$16, Ejercicios!$A:$B, 2, FALSE) * 0.6,"60%") -> 84 | J20: 6 | L20: =IFERROR(VLOOKUP($O$16, Ejercicios!$A:$B, 2, FALSE) * 0.6,"60%") -> 108 | M20: 8 | R20: =IFERROR(VLOOKUP($U$16, Ejercicios!$A:$B, 2, FALSE) * 0.6,"60%") -> 84 | X20: =IFERROR(VLOOKUP($AA$16, Ejercicios!$A:$B, 2, FALSE) * 0.6,"60%") -> 60% | AC20: =IFERROR(ROUND(VLOOKUP(Configuracion!$I$3 & Configuracion!$I$4, Calculos!$B$19:$L$28, 6, 0)*VLOOKUP(Configuracion!$I$5, Calculos!$A$14:$F$16, 3, 0)*VLOOKUP(ROUND(VLOOKUP(Configuracion!$I$3 & Configuracion!$I$4, Calculos!$B$19:$L$28, 11, 0),0)/100, Ref!$A$2:$K$22, 3, 0), 0),"") | AD20: =IFERROR(VLOOKUP($AG$16, Ejercicios!$A:$B, 2, FALSE) * 0.6,"60%") -> 60% | AI20: =IFERROR(ROUND(VLOOKUP(Configuracion!$I$3 & Configuracion!$I$4, Calculos!$B$19:$L$28, 6, 0)*VLOOKUP(Configuracion!$I$5, Calculos!$A$14:$F$16, 3, 0)*VLOOKUP(ROUND(VLOOKUP(Configuracion!$I$3 & Configuracion!$I$4, Calculos!$B$19:$L$28, 11, 0),0)/100, Ref!$A$2:$K$22, 3, 0), 0),"")
A21: =A20 -> 0 | B21: =B20 -> 0 | C21: =C20 -> 0 | D21: =D20 -> 0 | E21: =E20 -> 0 | F21: =IFERROR(VLOOKUP($I$16, Ejercicios!$A:$B, 2, FALSE) * 0.65,"65%") -> 91 | G21: 6 | H21: 4 | I21: 4 | L21: =IFERROR(VLOOKUP($O$16, Ejercicios!$A:$B, 2, FALSE) * 0.65,"65%") -> 117 | N21: 4 | O21: 6 | P21: 2 | R21: =IFERROR(VLOOKUP($U$16, Ejercicios!$A:$B, 2, FALSE) * 0.65,"65%") -> 91 | T21: 4 | X21: =IFERROR(VLOOKUP($AA$16, Ejercicios!$A:$B, 2, FALSE) * 0.65,"65%") -> 65% | AC21: =IFERROR(ROUND(VLOOKUP(Configuracion!$I$3 & Configuracion!$I$4, Calculos!$B$19:$L$28, 6, 0)*VLOOKUP(Configuracion!$I$5, Calculos!$A$14:$F$16, 3, 0)*VLOOKUP(ROUND(VLOOKUP(Configuracion!$I$3 & Configuracion!$I$4, Calculos!$B$19:$L$28, 11, 0),0)/100, Ref!$A$2:$K$22, 4, 0), 0),"") | AD21: =IFERROR(VLOOKUP($AG$16, Ejercicios!$A:$B, 2, FALSE) * 0.65,"65%") -> 65% | AI21: =IFERROR(ROUND(VLOOKUP(Configuracion!$I$3 & Configuracion!$I$4, Calculos!$B$19:$L$28, 6, 0)*VLOOKUP(Configuracion!$I$5, Calculos!$A$14:$F$16, 3, 0)*VLOOKUP(ROUND(VLOOKUP(Configuracion!$I$3 & Configuracion!$I$4, Calculos!$B$19:$L$28, 11, 0),0)/100, Ref!$A$2:$K$22, 4, 0), 0),"")
A22: =round(((VLOOKUP(Programacion!$I$2 & Programacion!$I$3, Calculos!$B$3:$L$12, 2, 0)/100)*Programacion!$I$13)*VLOOKUP((Programacion!$I$12+(VLOOKUP(Programacion!$I$2 & Programacion!$I$3, Calculos!$B$3:$L$12, 7, 0)))/100,Ref!$A$2:$K$22,5,0),0)-Entrenamiento!$G$22-Entrenamiento!$S$22-Entrenamiento!$Y$22-Entrenamiento!$AE$22-Entrenamiento!$M$22 -> 0 | B22: =ROUND(((VLOOKUP(Programacion!$I$2 & Programacion!$I$3, Calculos!$B$3:$L$12, 3, 0)/100)*Programacion!$I$13)*VLOOKUP((Programacion!$I$12+(VLOOKUP(Programacion!$I$2 & Programacion!$I$3, Calculos!$B$3:$L$12, 8, 0)))/100,Ref!$A$2:$K$22,5,0),0)-Entrenamiento!$H$22-Entrenamiento!$N$22-Entrenamiento!$T$22-Entrenamiento!$Z$22-Entrenamiento!$AF$22 -> 0 | C22: =round(((VLOOKUP(Programacion!$I$2 & Programacion!$I$3, Calculos!$B$3:$L$12, 4, 0)/100)*Programacion!$I$13)*VLOOKUP((Programacion!$I$12+(VLOOKUP(Programacion!$I$2 & Programacion!$I$3, Calculos!$B$3:$L$12, 9, 0)))/100,Ref!$A$2:$K$22,5,0),0)-Entrenamiento!$I$22-Entrenamiento!$O$22-Entrenamiento!$U$22-Entrenamiento!$AA$22-Entrenamiento!$AG$22 -> 0 | D22: =round(((VLOOKUP(Programacion!$I$2 & Programacion!$I$3, Calculos!$B$3:$L$12, 5, 0)/100)*Programacion!$I$13)*VLOOKUP((Programacion!$I$12+(VLOOKUP(Programacion!$I$2 & Programacion!$I$3, Calculos!$B$3:$L$12, 10, 0)))/100,Ref!$A$2:$K$22,5,0),0)-Entrenamiento!$J$22-Entrenamiento!$P$22-Entrenamiento!$V$22-Entrenamiento!$AB$22-Entrenamiento!$AH$22 -> 1 | E22: =round(((VLOOKUP(Programacion!$I$2 & Programacion!$I$3, Calculos!$B$3:$L$12, 6, 0)/100)*Programacion!$I$13)*VLOOKUP((Programacion!$I$12+(VLOOKUP(Programacion!$I$2 & Programacion!$I$3, Calculos!$B$3:$L$12, 11, 0)))/100,Ref!$A$2:$K$22,5,0),0)-Entrenamiento!$K$22-Entrenamiento!$Q$22-Entrenamiento!$W$22-Entrenamiento!$AC$22-Entrenamiento!$AI$22 -> 0 | F22: =IFERROR(VLOOKUP($I$16, Ejercicios!$A:$B, 2, FALSE) * 0.7,"70%") -> 98 | G22: 4 | H22: 5 | K22: 2 | L22: =IFERROR(VLOOKUP($O$16, Ejercicios!$A:$B, 2, FALSE) * 0.7,"70%") -> 126 | M22: 3 | N22: 4 | O22: 9 | P22: 2 | Q22: 2 | R22: =IFERROR(VLOOKUP($U$16, Ejercicios!$A:$B, 2, FALSE) * 0.7,"70%") -> 98 | S22: 2 | U22: 2 | V22: 3 | X22: =IFERROR(VLOOKUP($AA$16, Ejercicios!$A:$B, 2, FALSE) * 0.7,"70%") -> 70% | AC22: =IFERROR(ROUND(VLOOKUP(Configuracion!$I$3 & Configuracion!$I$4, Calculos!$B$19:$L$28, 5, 0)*VLOOKUP(Configuracion!$I$5, Calculos!$A$14:$F$16, 3, 0)*VLOOKUP(ROUND(VLOOKUP(Configuracion!$I$3 & Configuracion!$I$4, Calculos!$B$19:$L$28, 11, 0),0)/100, Ref!$A$2:$K$22, 5, 0), 0),"") | AD22: =IFERROR(VLOOKUP($AG$16, Ejercicios!$A:$B, 2, FALSE) * 0.7,"70%") -> 70% | AI22: =IFERROR(ROUND(VLOOKUP(Configuracion!$I$3 & Configuracion!$I$4, Calculos!$B$19:$L$28, 5, 0)*VLOOKUP(Configuracion!$I$5, Calculos!$A$14:$F$16, 3, 0)*VLOOKUP(ROUND(VLOOKUP(Configuracion!$I$3 & Configuracion!$I$4, Calculos!$B$19:$L$28, 11, 0),0)/100, Ref!$A$2:$K$22, 5, 0), 0),"")
A23: =round(((VLOOKUP(Programacion!$I$2 & Programacion!$I$3, Calculos!$B$3:$L$12, 2, 0)/100)*Programacion!$I$13)*VLOOKUP((Programacion!$I$12+(VLOOKUP(Programacion!$I$2 & Programacion!$I$3, Calculos!$B$3:$L$12, 7, 0)))/100,Ref!$A$2:$K$22,6,0),0)-Entrenamiento!$G$23-Entrenamiento!$S$23-Entrenamiento!$Y$23-Entrenamiento!$AE$23-Entrenamiento!$M$23 -> 0 | B23: =ROUND(((VLOOKUP(Programacion!$I$2 & Programacion!$I$3, Calculos!$B$3:$L$12, 3, 0)/100)*Programacion!$I$13)*VLOOKUP((Programacion!$I$12+(VLOOKUP(Programacion!$I$2 & Programacion!$I$3, Calculos!$B$3:$L$12, 8, 0)))/100,Ref!$A$2:$K$22,6,0),0)-Entrenamiento!$H$23-Entrenamiento!$N$23-Entrenamiento!$T$23-Entrenamiento!$Z$23-Entrenamiento!$AF$23 -> 0 | C23: =round(((VLOOKUP(Programacion!$I$2 & Programacion!$I$3, Calculos!$B$3:$L$12, 4, 0)/100)*Programacion!$I$13)*VLOOKUP((Programacion!$I$12+(VLOOKUP(Programacion!$I$2 & Programacion!$I$3, Calculos!$B$3:$L$12, 9, 0)))/100,Ref!$A$2:$K$22,6,0),0)-Entrenamiento!$I$23-Entrenamiento!$O$23-Entrenamiento!$U$23-Entrenamiento!$AA$23-Entrenamiento!$AG$23 -> 0 | D23: =round(((VLOOKUP(Programacion!$I$2 & Programacion!$I$3, Calculos!$B$3:$L$12, 5, 0)/100)*Programacion!$I$13)*VLOOKUP((Programacion!$I$12+(VLOOKUP(Programacion!$I$2 & Programacion!$I$3, Calculos!$B$3:$L$12, 10, 0)))/100,Ref!$A$2:$K$22,6,0),0)-Entrenamiento!$J$23-Entrenamiento!$P$23-Entrenamiento!$V$23-Entrenamiento!$AB$23-Entrenamiento!$AH$23 -> 0 | E23: =round(((VLOOKUP(Programacion!$I$2 & Programacion!$I$3, Calculos!$B$3:$L$12, 6, 0)/100)*Programacion!$I$13)*VLOOKUP((Programacion!$I$12+(VLOOKUP(Programacion!$I$2 & Programacion!$I$3, Calculos!$B$3:$L$12, 11, 0)))/100,Ref!$A$2:$K$22,6,0),0)-Entrenamiento!$K$23-Entrenamiento!$Q$23-Entrenamiento!$W$23-Entrenamiento!$AC$23-Entrenamiento!$AI$23 -> 0 | F23: =IFERROR(VLOOKUP($I$16, Ejercicios!$A:$B, 2, FALSE) * 0.75,"75%") -> 105 | G23: 6 | H23: 2 | I23: 6 | J23: 5 | K23: 2 | L23: =IFERROR(VLOOKUP($O$16, Ejercicios!$A:$B, 2, FALSE) * 0.75,"75%") -> 135 | M23: 2 | N23: 2 | O23: 6 | P23: 3 | Q23: 2 | R23: =IFERROR(VLOOKUP($U$16, Ejercicios!$A:$B, 2, FALSE) * 0.75,"75%") -> 105 | S23: 2 | T23: 6 | X23: =IFERROR(VLOOKUP($AA$16, Ejercicios!$A:$B, 2, FALSE) * 0.75,"75%") -> 75% | AC23: =IFERROR(ROUND(VLOOKUP(Configuracion!$I$3 & Configuracion!$I$4, Calculos!$B$19:$L$28, 6, 0)*VLOOKUP(Configuracion!$I$5, Calculos!$A$14:$F$16, 3, 0)*VLOOKUP(ROUND(VLOOKUP(Configuracion!$I$3 & Configuracion!$I$4, Calculos!$B$19:$L$28, 11, 0),0)/100, Ref!$A$2:$K$22, 6, 0), 0),"") | AD23: =IFERROR(VLOOKUP($AG$16, Ejercicios!$A:$B, 2, FALSE) * 0.75,"75%") -> 75% | AI23: =IFERROR(ROUND(VLOOKUP(Configuracion!$I$3 & Configuracion!$I$4, Calculos!$B$19:$L$28, 6, 0)*VLOOKUP(Configuracion!$I$5, Calculos!$A$14:$F$16, 3, 0)*VLOOKUP(ROUND(VLOOKUP(Configuracion!$I$3 & Configuracion!$I$4, Calculos!$B$19:$L$28, 11, 0),0)/100, Ref!$A$2:$K$22, 6, 0), 0),"")
